Workbook

Sheet 获取清单
A1: 文献获取清单 · 长江文化 × 游戏化文化传播 × AI文化IP 文献库 v1.0
A2: 共 106 条。黄色底色的「获取状态」列是给你填的，其余为只读信息。当前全部为「未获取」——建库环境无法联网下载，请在本机运行 download_oa_pdfs.sh。
A4: 编号 | B4: 分组 | C4: 子组 | D4: 优先级 | E4: 标记 | F4: 标题 | G4: 年份 | H4: 出处 | I4: DOI | J4: 获取方式 | K4: 获取状态 | L4: 链接 | M4: 备注
A5: A1-1 | B5: A 文化游戏化转译与文化学习 | C5: A-1 直接前序 | D5: 必读 | F5: Beyond entertainment: how intangible cultural heritage in video games shapes youth cultural identity | G5: 2026 | H5: 2026, Frontiers in Psychology | I5: 10.3389/fpsyg.2026.1855866 | J5: ① 脚本自动下载 | K5: 未获取 | L5: 打开 | M5: 运行 download_oa_pdfs.sh 自动抓取
A6: A1-2 | B6: A 文化游戏化转译与文化学习 | C6: A-1 直接前序 | D6: 必读 | E6: 量表·方法 | F6: Integrating intangible cultural heritage elements into mobile games: an exploration of player cultural identity | G6: 2026 | H6: 2026, Information Technology & People, 39(1) | I6: 10.1108/ITP-01-2024-0088 | J6: ③ 需订阅·走图书馆 | K6: 未获取 | L6: 打开 | M6: 湖工大图书馆 CNKI / Web of Science / ScienceDirect 镜像
A7: A1-3 | B7: A 文化游戏化转译与文化学习 | C7: A-1 直接前序 | D7: 必读 | E7: 量表·方法 | F7: Enhancing handicraft intangible cultural heritage learning through immersive VR serious games: a multimodal study on natural interaction effectiveness | G7: 2026 | H7: 2026, Frontiers in Psychology | I7: 10.3389/fpsyg.2026.1880795 | J7: ① 脚本自动下载 | K7: 未获取 | L7: 打开 | M7: 运行 download_oa_pdfs.sh 自动抓取
A8: A1-4 | B8: A 文化游戏化转译与文化学习 | C8: A-1 直接前序 | E8: 量表·方法 | F8: The art and science of serious game design: a quasi-experimental study based on self-determination theory in traditional Chinese culture education | G8: 2025 | H8: 2025, Frontiers in Psychology | I8: 10.3389/fpsyg.2025.1536513 | J8: ① 脚本自动下载 | K8: 未获取 | L8: 打开 | M8: 运行 download_oa_pdfs.sh 自动抓取
A9: A1-5 | B9: A 文化游戏化转译与文化学习 | C9: A-1 直接前序 | F9: Understanding the key factors influencing continued use intention toward ICH-themed virtual reality games | G9: 2026 | H9: 2026, Frontiers in Virtual Reality | I9: 10.3389/frvir.2026.1833878 | J9: ① 脚本自动下载 | K9: 未获取 | L9: 打开 | M9: 运行 download_oa_pdfs.sh 自动抓取
A10: A1-6 | B10: A 文化游戏化转译与文化学习 | C10: A-1 直接前序 | F10: The Model and Application of the Serious Game for Cultural Heritage Education: A Case Study of Kuliang, China | G10: 2025 | H10: 2025, Lin, Zhou & Guan | I10: 10.1177/01678329251323449 | J10: ③ 需订阅·走图书馆 | K10: 未获取 | L10: 打开 | M10: 湖工大图书馆 CNKI / Web of Science / ScienceDirect 镜像
A11: A1-7 | B11: A 文化游戏化转译与文化学习 | C11: A-1 直接前序 | F11: Becoming a Xia: Constructing Cultural Identity in the History of Wuxia Games in China | G11: 2025 | H11: 2025, Cao, Zhou & Feng, Games and Culture | I11: 10.1177/15554120231208735 | J11: ③ 需订阅·走图书馆 | K11: 未获取 | L11: 打开 | M11: 湖工大图书馆 CNKI / Web of Science / ScienceDirect 镜像
A12: A1-8 | B12: A 文化游戏化转译与文化学习 | C12: A-1 直接前序 | F12: Cultural Affordance and Reception: A Theoretical Framework for Interactive Cross-Cultural Sense-Making in Video Game Environments | G12: 2025 | H12: 2025, Yu, Guo, Shen & Chen, Games and Culture | I12: 10.1177/15554120251336564 | J12: ③ 需订阅·走图书馆 | K12: 未获取 | L12: 打开 | M12: 湖工大图书馆 CNKI / Web of Science / ScienceDirect 镜像
A13: A1-9 | B13: A 文化游戏化转译与文化学习 | C13: A-1 直接前序 | F13: Enhancing Young Generation's Heritage Identity Through Emotional Responses to Virtual Cultural Heritage Experience: A Design Case with Azheke Community at Hani Rice Terraces | G13: 2025 | H13: 2025, IJHCI, 42(1) | I13: 10.1080/10447318.2025.2505159 | J13: ③ 需订阅·走图书馆 | K13: 未获取 | L13: 打开 | M13: 湖工大图书馆 CNKI / Web of Science / ScienceDirect 镜像
A14: A1-10 | B14: A 文化游戏化转译与文化学习 | C14: A-1 直接前序 | F14: Evaluating knowledge transfer mechanisms and outcomes of VR/AR for cultural-heritage serious games | G14: 2025 | H14: 2025, npj Heritage Science | I14: 10.1038/s40494-025-02247-z | J14: ① 脚本自动下载 | K14: 未获取 | L14: 打开 | M14: 运行 download_oa_pdfs.sh 自动抓取
A15: A2-1 | B15: A 文化游戏化转译与文化学习 | C15: A-2 效应量与方法基准 | D15: 必读 | E15: 量表·方法 | F15: Exploring the Efficacy of Game-Based Pedagogy: A Three-Level Meta-Analysis of Game-Based Learning and Gamification | G15: 2026 | H15: 2026, Xu & Dai | I15: 10.1177/14697874261424519 | J15: ③ 需订阅·走图书馆 | K15: 未获取 | L15: 打开 | M15: 湖工大图书馆 CNKI / Web of Science / ScienceDirect 镜像
A16: A2-2 | B16: A 文化游戏化转译与文化学习 | C16: A-2 效应量与方法基准 | E16: 量表·方法 | F16: Effectiveness of Augmented Reality and Virtual Reality Interventions on Learning Outcomes: A Meta-Analysis in Higher Education | G16: 2025 | H16: 2025, TechTrends | I16: 10.1007/s11528-025-01106-9 | J16: ③ 需订阅·走图书馆 | K16: 未获取 | L16: 打开 | M16: 湖工大图书馆 CNKI / Web of Science / ScienceDirect 镜像
A17: A2-3 | B17: A 文化游戏化转译与文化学习 | C17: A-2 效应量与方法基准 | E17: 量表·方法 | F17: Wouters, van Nimwegen, van Oostendorp & van der Spek (2013). A meta-analysis of the cognitive and motivational effects of serious games | H17: Journal of Educational Psychology, 105(2) | J17: ③ 需订阅·走图书馆 | K17: 未获取 | M17: 湖工大图书馆 CNKI / Web of Science / ScienceDirect 镜像
A18: A2-4 | B18: A 文化游戏化转译与文化学习 | C18: A-2 效应量与方法基准 | E18: 量表·方法 | F18: Wouters & van Oostendorp (2013). A meta-analytic review of the role of instructional support in game-based learning | H18: Computers & Education, 60(1) | J18: ① 脚本自动下载 | K18: 未获取 | L18: 打开 | M18: 运行 download_oa_pdfs.sh 自动抓取
A19: A2-5 | B19: A 文化游戏化转译与文化学习 | C19: A-2 效应量与方法基准 | F19: Effectiveness of digital educational game and game design in STEM learning: a meta-analytic review | G19: 2023 | H19: 2023, IJ STEM Education | I19: 10.1186/s40594-022-00344-0 | J19: ① 脚本自动下载 | K19: 未获取 | L19: 打开 | M19: 运行 download_oa_pdfs.sh 自动抓取
A20: A2-6 | B20: A 文化游戏化转译与文化学习 | C20: A-2 效应量与方法基准 | F20: Effects of digital game-based STEM education on students' learning achievement: a meta-analysis | G20: 2022 | H20: 2022, IJ STEM Education | I20: 10.1186/s40594-022-00344-0 | J20: ① 脚本自动下载 | K20: 未获取 | L20: 打开 | M20: 运行 download_oa_pdfs.sh 自动抓取
A21: A2-7 | B21: A 文化游戏化转译与文化学习 | C21: A-2 效应量与方法基准 | F21: Gamification enhances student intrinsic motivation, perceptions of autonomy and relatedness, but minimal impact on competency: a meta-analysis | G21: 2024 | H21: 2024, ETR&D | I21: 10.1007/s11423-023-10337-7 | J21: ③ 需订阅·走图书馆 | K21: 未获取 | L21: 打开 | M21: 湖工大图书馆 CNKI / Web of Science / ScienceDirect 镜像
A22: A2-8 | B22: A 文化游戏化转译与文化学习 | C22: A-2 效应量与方法基准 | F22: Gamification design in cultural heritage education: A systematic literature review (2019–2024) | J22: ② 免费·浏览器另存 | K22: 未获取 | L22: 打开 | M22: 浏览器打开链接后另存为 PDF
A23: A3-1 | B23: A 文化游戏化转译与文化学习 | C23: A-3 理论与量表基座 | D23: 必读 | E23: 量表·方法 | F23: Jennett, Cox, Cairns, Dhoparee, Epps, Tijs & Walton (2008). Measuring and defining the experience of immersion in games | H23: International Journal of Human-Computer Studies, 66(9), 641–661) — 被引 1800+ | J23: ① 脚本自动下载 | K23: 未获取 | L23: 打开 | M23: 运行 download_oa_pdfs.sh 自动抓取
A24: A3-2 | B24: A 文化游戏化转译与文化学习 | C24: A-3 理论与量表基座 | D24: 必读 | E24: 量表·方法 | F24: Green & Brock (2000). The role of transportation in the persuasiveness of public narratives | H24: Journal of Personality and Social Psychology, 79(5), 701–721) — 经典 | J24: ① 脚本自动下载 | K24: 未获取 | L24: 打开 | M24: 运行 download_oa_pdfs.sh 自动抓取
A25: A3-3 | B25: A 文化游戏化转译与文化学习 | C25: A-3 理论与量表基座 | E25: 量表·方法 | F25: van Laer, de Ruyter, Visconti & Wetzels (2014). The Extended Transportation-Imagery Model: A Meta-Analysis | H25: Journal of Consumer Research, 40(5), 797–817 | J25: ① 脚本自动下载 | K25: 未获取 | L25: 打开 | M25: 运行 download_oa_pdfs.sh 自动抓取
A26: A3-4 | B26: A 文化游戏化转译与文化学习 | C26: A-3 理论与量表基座 | D26: 必读 | E26: 量表·方法 | F26: Ryan, Rigby & Przybylski (2006). The motivational pull of video games: A self-determination theory approach | H26: Motivation and Emotion, 30(4)) — 经典 | I26: 10.1007/s11031-006-9051-8 | J26: ① 脚本自动下载 | K26: 未获取 | L26: 打开 | M26: 运行 download_oa_pdfs.sh 自动抓取
A27: A3-5 | B27: A 文化游戏化转译与文化学习 | C27: A-3 理论与量表基座 | E27: 量表·方法 | F27: Przybylski, Rigby & Ryan (2010). A motivational model of video game engagement | H27: Review of General Psychology | J27: ① 脚本自动下载 | K27: 未获取 | L27: 打开 | M27: 运行 download_oa_pdfs.sh 自动抓取
A28: A3-6 | B28: A 文化游戏化转译与文化学习 | C28: A-3 理论与量表基座 | E28: 量表·方法 | F28: Sweetser & Wyeth (2005). GameFlow: A model for evaluating player enjoyment in games | H28: Computers in Entertainment, 3(3) | I28: 10.1145/1077246.1077253 | J28: ① 脚本自动下载 | K28: 未获取 | L28: 打开 | M28: 运行 download_oa_pdfs.sh 自动抓取
A29: A3-7 | B29: A 文化游戏化转译与文化学习 | C29: A-3 理论与量表基座 | E29: 量表·方法 | F29: Hamari, Koivisto & Sarsa (2014). Does gamification work? — A literature review of empirical studies on gamification | H29: HICSS | J29: ① 脚本自动下载 | K29: 未获取 | L29: 打开 | M29: 运行 download_oa_pdfs.sh 自动抓取
A30: A3-8 | B30: A 文化游戏化转译与文化学习 | C30: A-3 理论与量表基座 | E30: 量表·方法 | F30: Koivisto & Hamari (2019). The rise of motivational information systems: A review of gamification research | H30: International Journal of Information Management, 45, 191–210 | J30: ③ 需订阅·走图书馆 | K30: 未获取 | L30: 打开 | M30: 湖工大图书馆 CNKI / Web of Science / ScienceDirect 镜像
A31: A3-9 | B31: A 文化游戏化转译与文化学习 | C31: A-3 理论与量表基座 | E31: 量表·方法 | F31: Falk & Storksdieck (2005). Using the contextual model of learning to understand visitor learning from a science center exhibition | H31: Science Education, 89(5) | I31: 10.1002/sce.20078 | J31: ③ 需订阅·走图书馆 | K31: 未获取 | L31: 打开 | M31: 湖工大图书馆 CNKI / Web of Science / ScienceDirect 镜像
A32: A3-10 | B32: A 文化游戏化转译与文化学习 | C32: A-3 理论与量表基座 | F32: Falk & Dierking. Learning from Museums: Visitor Experiences and the Making of Meaning（专著） | J32: ④ 专著·借阅或购买 | K32: 未获取 | M32: 图书馆借阅或购买纸质/电子书
A33: A4-1 | B33: A 文化游戏化转译与文化学习 | C33: A-4 场景对照 | E33: 量表·方法 | F33: Can Location-Based Augmented Reality Support Cultural-Heritage Experience in Real-World Settings? Age-Related Engagement Patterns and a Field-Based Evaluation | G33: 2026 | H33: 2026, Informatics, 13(1) | I33: 10.3390/informatics13010012 | J33: ① 脚本自动下载 | K33: 未获取 | L33: 打开 | M33: 运行 download_oa_pdfs.sh 自动抓取
A34: A4-2 | B34: A 文化游戏化转译与文化学习 | C34: A-4 场景对照 | F34: How Do Location-Based AR Games Enhance Value Co-Creation Experiences at Cultural Heritage Sites? A Process Perspective | G34: 2024 | H34: 2024, Applied Sciences, 14(15) | I34: 10.1145/3700881 | J34: ① 脚本自动下载 | K34: 未获取 | L34: 打开 | M34: 运行 download_oa_pdfs.sh 自动抓取
A35: A4-3 | B35: A 文化游戏化转译与文化学习 | C35: A-4 场景对照 | F35: HeritageSite AR: Design and Evaluation of a Mobile AR Exploration Game for a Chinese Heritage Site | G35: 2024 | H35: 2024, JOCCH | I35: 10.1145/3700881 | J35: ③ 需订阅·走图书馆 | K35: 未获取 | L35: 打开 | M35: 湖工大图书馆 CNKI / Web of Science / ScienceDirect 镜像
A36: A4-4 | B36: A 文化游戏化转译与文化学习 | C36: A-4 场景对照 | F36: Design of a virtual reality serious game for experiencing the colors of Dunhuang frescoes | G36: 2024 | H36: 2024, npj Heritage Science | I36: 10.1038/s40494-024-01477-x | J36: ① 脚本自动下载 | K36: 未获取 | L36: 打开 | M36: 运行 download_oa_pdfs.sh 自动抓取
A37: A4-5 | B37: A 文化游戏化转译与文化学习 | C37: A-4 场景对照 | F37: Collaboration in an immersive VR Edu-Metaverse improves knowledge gain and retention of concise cultural heritage content | G37: 2026 | H37: 2026, Virtual Reality | I37: 10.1007/s10055-026-01436-w | J37: ③ 需订阅·走图书馆 | K37: 未获取 | L37: 打开 | M37: 湖工大图书馆 CNKI / Web of Science / ScienceDirect 镜像
A38: A4-6 | B38: A 文化游戏化转译与文化学习 | C38: A-4 场景对照 | F38: Metaverse and XR for cultural heritage education: applications, standards, architecture | G38: 2025 | H38: 2025, Virtual Reality | I38: 10.3390/heritage8100421 | J38: ③ 需订阅·走图书馆 | K38: 未获取 | L38: 打开 | M38: 湖工大图书馆 CNKI / Web of Science / ScienceDirect 镜像
A39: A4-7 | B39: A 文化游戏化转译与文化学习 | C39: A-4 场景对照 | F39: Augmented Reality in Cultural Heritage: A Narrative Review of Design, Development and Evaluation Approaches | G39: 2025 | H39: 2025, Heritage, 8(10) | I39: 10.3390/educsci13010047 | J39: ① 脚本自动下载 | K39: 未获取 | L39: 打开 | M39: 运行 download_oa_pdfs.sh 自动抓取
A40: A4-8 | B40: A 文化游戏化转译与文化学习 | C40: A-4 场景对照 | F40: Serious Games in Cultural Heritage: A Review of Practices and Considerations in the Design of Location-Based Games | G40: 2023 | H40: 2023, Education Sciences, 13(1) | I40: 10.3390/app12178476 | J40: ① 脚本自动下载 | K40: 未获取 | L40: 打开 | M40: 运行 download_oa_pdfs.sh 自动抓取
A41: A4-9 | B41: A 文化游戏化转译与文化学习 | C41: A-4 场景对照 | F41: VR Games in Cultural Heritage: A Systematic Review | G41: 2022 | H41: 2022, Applied Sciences, 12(17) | I41: 10.1038/s40494-025-02162-3 | J41: ① 脚本自动下载 | K41: 未获取 | L41: 打开 | M41: 运行 download_oa_pdfs.sh 自动抓取
...

Sheet 统计
A1: 获取进度统计
A2: 本表全部为公式，你在「获取清单」K 列改了状态，这里会自动更新。
A4: 按获取方式
A5: 获取方式 | B5: 条数 | C5: 已下载 | D5: 待办
A6: ① 脚本自动下载 | B6: =COUNTIF(获取清单!$J$5:$J$110,A6) -> 50 | C6: =COUNTIFS(获取清单!$J$5:$J$110,A6,获取清单!$K$5:$K$110,"已下载") -> 0 | D6: =B6-C6 -> 50
A7: ② 免费·浏览器另存 | B7: =COUNTIF(获取清单!$J$5:$J$110,A7) -> 15 | C7: =COUNTIFS(获取清单!$J$5:$J$110,A7,获取清单!$K$5:$K$110,"已下载") -> 0 | D7: =B7-C7 -> 15
A8: ③ 需订阅·走图书馆 | B8: =COUNTIF(获取清单!$J$5:$J$110,A8) -> 39 | C8: =COUNTIFS(获取清单!$J$5:$J$110,A8,获取清单!$K$5:$K$110,"已下载") -> 0 | D8: =B8-C8 -> 39
A9: ④ 专著·借阅或购买 | B9: =COUNTIF(获取清单!$J$5:$J$110,A9) -> 2 | C9: =COUNTIFS(获取清单!$J$5:$J$110,A9,获取清单!$K$5:$K$110,"已下载") -> 0 | D9: =B9-C9 -> 2
A10: 合计 | B10: =SUM(B6:B9) -> 106 | C10: =SUM(C6:C9) -> 0 | D10: =SUM(D6:D9) -> 106
A12: 按分组
A13: 分组 | B13: 条数 | C13: 已下载
A14: A 文化游戏化转译与文化学习 | B14: =COUNTIF(获取清单!$B$5:$B$110,A14) -> 39 | C14: =COUNTIFS(获取清单!$B$5:$B$110,A14,获取清单!$K$5:$K$110,"已下载") -> 0
A15: B AI文化角色与智能化传播 | B15: =COUNTIF(获取清单!$B$5:$B$110,A15) -> 45 | C15: =COUNTIFS(获取清单!$B$5:$B$110,A15,获取清单!$K$5:$K$110,"已下载") -> 0
A16: C 跨媒介文化IP与虚实外溢 | B16: =COUNTIF(获取清单!$B$5:$B$110,A16) -> 15 | C16: =COUNTIFS(获取清单!$B$5:$B$110,A16,获取清单!$K$5:$K$110,"已下载") -> 0
A17: D 武汉—长江本地与政策 | B17: =COUNTIF(获取清单!$B$5:$B$110,A17) -> 7 | C17: =COUNTIFS(获取清单!$B$5:$B$110,A17,获取清单!$K$5:$K$110,"已下载") -> 0
A19: 必读篇目进度
A20: 必读总数 | B20: =COUNTIF(获取清单!$D$5:$D$110,"必读") -> 22
A21: 必读中已下载 | B21: =COUNTIFS(获取清单!$D$5:$D$110,"必读",获取清单!$K$5:$K$110,"已下载") -> 0
A22: 必读完成率 | B22: =IFERROR(B21/B20,0) -> 0

Sheet 说明
A1: 怎么用这份清单
A3: 当前状态
A4: 全部 106 条都是「未获取」。建库所在的远程环境出网被网络策略限制（arXiv、MDPI、Frontiers、Nature、ACL 等全部返回 403），所以一篇 PDF 都没能在那边抓下来。下面的步骤需要在你自己的电脑上做。
A6: 第一步：跑脚本，拿下 ① 类的 50 篇
A7: 把 download_oa_pdfs.sh 和这份清单放在同一个文件夹，然后：
A8: bash download_oa_pdfs.sh
A9: PDF 会存进 pdfs/ 子目录。跑完会生成 下载结果.csv，逐条写明成功 / 跳过 / 失败，直接用 Excel 打开就能看。
A10: Windows 没有 bash 的话：用 Git Bash，或在 WSL / Mac / Linux 终端里跑。
A12: 第二步：把 下载结果.csv 的结果抄回 K 列
A13: 或者更省事：按 K 列筛选「未获取」，对照 pdfs/ 目录里已有的文件逐条改。
A15: 第三步：② 类 15 篇，浏览器手动存
A16: 这些是开放获取，但站点有反爬或是网页正文，脚本抓不稳。点 L 列的「打开」，在浏览器里另存为 PDF 即可。
... A31: 填了 K 列之后，切到「统计」表可以看到进度自动更新。
